Workbook
Name ConcUnit: [1]Concrete!$G$61
Name ConcUnitM: 'ICE Summary'!$G$267
Name ConcUnitM: #REF!
Name ICESummary: '[2]ICE Readable'!$K$6:$CZ$1003

Sheet FRONT
E6: ICE (Inventory of Carbon & Energy)
H8: All authors are listed alphabetically
F10: Current Authors: | H10: Circular Ecology*
F11: Affiliation:
G14: *corresponding author. Contact details: http://www.circularecology.com/contact.html
E15: Version Control
G16: Version: | H16: Educational
G17: Version Number: | H17: =Miscellaneous!E3 -> V4.1 - Oct 2025
E19: Users are required to Register for Permission to use the data for Non-educational Use. Registration is Free. Use the link below and fill in the form on the webpage. Educational use does not require registration, but it is encouraged to register to support the ICE Database.
E20: Is this version still valid? | G20: Check link below, to see if a newer version is available.
E21: Register for permission to use the data for non educational use and to check if this copy is up to date at: | G21: http://www.circularecology.com/embodied-energy-and-carbon-footprint-database.html
E23: Acknowledgments
E24: The authors are grateful to the below organisations, who have provided funding to update this version of the ICE database.
E25: Version | G25: Funded by:
E26: ICE V 4.0 & 4.1
H27: The latest version was funded by (appearing alphabetically):
H28: BCIS
H30: Circular Ecology
H33: Innovate UK
E36: Previous versions | G36: Please see the Acknowledgements page for details of previous funders.
E39: Authors
F42: Original Authors: | H42: Dr Craig Jones (Circular Ecology) | J42: Professor Geoffrey Hammond (University of Bath)
F44: Circular Ecology Current Authors: | H44: Jon Burrow (Oversight), Dr Craig Jones (QA), Joe Rouse (Project Manager), Charlie Zhu (Lead Analyst), Vaishnavi Unnad, Kit Wickens, Thomas Relph, Liam Seprini, Edwin Lowe.
F46: Previous Contributors: | H46: S. Vernon (PM), W. Garner (PM), J. Pearce, K. Dävé, B. Sodagar, M. Brill, A. Ranathungage.

Sheet Acknowledgements
E6: ICE Acknowledgements
E8: Authors
F11: Original Authors: | H11: Dr Craig Jones (Circular Ecology) | J11: Professor Geoffrey Hammond (University of Bath)
F13: Circular Ecology Current Authors: | H13: Jon Burrow (Oversight), Dr Craig Jones (QA), Joe Rouse (Project Manager, PM), Charlie Zhu (Lead Analyst), Vaishnavi Unnad, Kit Wickens, Thomas Relph, Liam Seprini, Edwin Lowe.
F15: Previous Contributors: | H15: S. Vernon (PM), W. Garner (PM), J. Pearce, K. Dävé, B. Sodagar, M. Brill, A. Ranathungage.
E19: Main Funders
E20: Version | G20: Funded by:
E21: ICE V 4.0 & 4.1
H22: The latest version was funded by (appearing alphabetically):
H24: BCIS
H26: Circular Ecology
H28: Innovate UK
E33: Contributors
E34: The authors are grateful to the below organisations, who have provided contributions to the ICE database.
E35: Version | G35: Contribution:
E36: ICE V 4.0
H38: Anglian Water | I38: Funded update data for Stainless Steel (no conflict of interest confirmed).
H40: xbim | I40: Circular Ecology were included as a partner in an Innovate UK funded project called Net Zero Flow, which part covered some of the research time of the background ICE Database.
H41: Morgan Sindall | I41: Circular Ecology were included as a sub-contractor in an Innovate UK funded project.
E44: Previous Acknowledgments
E45: The authors are grateful to the below organisations, who have previously provided funding to update the ICE database.
E46: Version | G46: Funded by:
E47: ICE V 3.0
H48: This version was funded by (appearing alphabetically):
H49: Environment Agency
H50: Heathrow Airport
H51: Rail Safety and Standards Board (RSSB)
E53: Previous versions | G53: The original ICE database was joint funded under the Carbon Vision Buildings program by the Engineering and Physical Sciences Research Council (EPSRC) and the Carbon Trust (before they became a private organisation), at the University of Bath.

Sheet Support ICE
E6: Support the ICE Database
F10: The ICE Database is a free resource. Circular Ecology are committed to keeping it freely available. However, the reality is that funds need to be raised to cover the maintenance and development of the database. Updates have been too infrequent, being in 2011, 2019 and more recently 2024. The embodied carbon landscape has changed immeasurably over that time, but the ICE database wasn’t updated enough to reflect this. We intend to change this and plan to bring all the old data up to date (various data is still from the 2011 version). We also hope to expand the database in the future. In order to help raise the funds for the maintenance and development of the ICE database, we have developed a supporter system. Contributions are optional for all users. This will recognise organisations that have made contributions to the ICE database, with several levels of support to suit different organisation sizes.
F17: Read more about the ICE Supporter System: | G17: https://circularecology.com/ice-supporter-system.html

Sheet TERMS OF USE
E6: ICE (Inventory of Carbon & Energy) Terms of Use
F7: REGISTRATION FOR PERMISSION TO USE THE DATA FOR NON-EDUCATIONAL USE
F8: Users are required to register for permission to use the data for non-educational applications. Registration is free and lasts until 30th June 2026. Once the initial registration has elapsed, users may re-register for free to cover a further 12 month period from the date of registration.
F9: Register for permission to use the ICE Database for non-educational use: | G9: https://circularecology.com/RegisterICE.html
F10: TERMS OF USE
F11: Users are required to adhere fully to the latest Terms of Use.
F12: Terms of Use: | G12: https://circularecology.com/terms-of-use.html
F13: Below are some of the terms of use for the Inventory of Carbon & Energy (ICE) database, which must be abided by (list not comprehensive, please check full terms of use at the above webpage): - Users are required to register for permission to use the data for non-educational uses. The registration is free and lasts up to 12 months. Once the period has elapsed, users can complete another free registration for the next 12 months. - The ICE database will only be valid for use for non-educational uses for a maximum of 3 years from the published date on the version number. After the 3 year period has elapsed, the data shall only be used for educational uses. This 3 year period is separate to the need to register for permission to use the data. It will encourage the database to be updated more frequency than it has in the past. - The ICE database must not be distributed nor uploaded to websites without the written permission of the authors. Instead the link to the download website should be referred to, which will always contain the most recent version of the database, http://www.circularecology.com/embodied-energy-and-carbon-footprint-database.html. - The data contained within the ICE database may be used on projects and within carbon tools - so long as registration is completed for permission to use, and so long as full reference to the database is provided and with a link to the download website to ensure readers can check for the most recent version of the ICE database. - The ICE database shall not be reproduced, copied, distributed, published, modified or in any way exploited, in whole or in part. - The disclaimer below shall be adhered to.
F14: DISCLAIMER
F15: Whilst efforts have been made to ensure the accuracy of the information contained in the Inventory of Carbon & Energy (ICE), the content is subject to change and the authors and their affiliated organisations cannot guarantee its accuracy or currency. The right is reserved to make changes to the information without notice. The information is consequently provided "as is" without any representation or warranty as to accuracy, currency, quality or fitness for purpose of any kind. You should independently verify any information contained in ICE before relying on it. The authors and their affiliated organisations do not make any representation nor give any warranty as to the ownership of the copyright of any material forming part of ICE and does not accept any liability for any direct, indirect, incidental or consequential losses arising from the infringement of any third party rights in relation to any material in ICE.

Sheet Contents - Navigation
E6: ICE (Inventory of Carbon & Energy) Contents
E7: Attention is drawn to these areas of the ICE database:
E8: Content | F8: Description
E9: Terms of use | F9: See terms of use worksheet.
E10: Glossary of terms | F10: A glossary of terms.
E11: Method | F11: Notes on the method and boundaries.
E12: Update Notes | F12: Notes on the key changes in this version of the ICE database.
E13: Data Quality Matrix | F13: A data quality matrix is applied to judge data quality.
E14: Main ICE Database Summary Table | F14: This summaries all of the data in the ICE database, on one worksheet. For more information on each material, see the material profiles.
E15: Material profiles | F15: A material profile is presented for each of the main materials, such as cement, concrete, steel, timber…etc. Here you will find a lot more data, such as statistics, references and further information.
E16: References | F16: For the references in this version of ICE, see the material profiles, there is a references section on each worksheet. For references from ICE V2.0, see the worksheet at the end of this workbook.
E17: Calculator for cement, mortar and concrete | F17: See separate excel file, distributed with the ICE database.
E18: Calculator for steel, to modify recycled content and recyclability assumptions | F18: See the material profile for steel.
E19: Calculator for precast concrete | F19: See material profile for concrete. Also see concrete on the main summary table.
E20: Data quality scores | F20: See the material profiles

Sheet >> Background >>
E6: Background Information >>>

Sheet Glossary
E6: ICE (Inventory of Carbon & Energy) Glossary
E7: Find below a glossary of terms.
E10: Term | F10: Description
E11: Allocation | F11: The sub-division of input and output flows between one or more product systems. Also applies to recycling methodology.
E12: Biogenic | F12: Derived from living organisms, but not from fossil origin, e.g. biomass is considered biogenic, but coal is not.
E13: (System) Boundaries | F13: A set of criteria that defines which processes are included within the (boundaries of) assessment.
E14: By-product | F14: Material that is a sub-derivative of the processing operations but is considered to have an economic value (e.g. facilitated by an application and market demand).
E15: Calorific Value (CV) of energy | F15: The energy content of a fuel (as may be released through combustion). It may be expressed as a Gross Calorific Value (GCV) or Net Calorific Value (NCV). The former is always larger than (or equal to) the latter. The difference is due to latent heat (energy) remaining in condensation (water vapour) after combustion. The difference is typically 5-12 per cent (examples, 11 per cent for natural gas, 5 per cent for coal).
E16: Capital carbon | F16: Capital carbon is a term that is mainly used for intrastate projects, to denote embodied carbon of the infrastructure construction project. It can be confusing when reading older background literature, who would use the term capital energy, as described below.
E17: Capital energy | F17: Energy required to manufacture capital inputs (e.g. ancillary infrastructure, such as buildings, machinery, tools). See also capital carbon.
E18: Carbon dioxide equivalent (CO2e) | F18: See Global Warming Potential (GWP).
E19: Carbon storage | F19: See carbon sequestration.
E20: Carbon sequestration | F20: The extraction of carbon from the atmosphere, for example from trees and plants.
E21: Co-product | F21: Material or product that is produced alongside the investigated product, i.e. co-production.
... E53: EOL | F53: End of life

Sheet Method and Update Notes
E7: ICE (Inventory of Carbon & Energy) V4.1
E8: Note on scope of this update: The ICE database version 4.1 contains updates to a small number of materials (bitumen and GGBS), but these materials have large changes in their embodied carbon and influence several important construction materials. The majority of material categories are unaffected by this update. Data for other materials is still presented from the previous versions of the ICE database (V4.0, V3.0 and V2.0) for completeness. Users should consider that data from ICE V3.0 was published in 2019, and data from ICE V2.0 was published in 2011.
E11: ICE (Inventory of Carbon & Energy) Background
E12: The Inventory of Carbon and Energy (ICE) was initially created by Craig Jones, under the supervision of Professor Geoffrey Hammond, whilst working as a researcher at the University of Bath. Work started in 2004. Versions were released periodically over the period 2005-2011. The original research project was funded by the Engineering and Physical Sciences Research Council (EPSRC) and the Carbon Trust (before they became a private company). The project involved assessing the implications of embodied energy and carbon in construction for new UK buildings. The Inventory was created to provide a freely available, robust and reliable source of data for the materials used in the construction process for the project partners. It soon became obvious that this data would be of interest to a wide range of users beyond the project partners. Subsequently, in 2006 the ICE database was made available for download from the authors website. Since then it has been downloaded by over 50,000 professional users from industry, academia, government departments and agencies around the world.
E16: ICE (Inventory of Carbon & Energy) Method
E17: The ICE database is essentially a meta-database. It is based upon a large literature review, where data is collected and compiled on the embodied carbon of construction materials. There is a background database, which stores embodied carbon datapoints collected from the literature. That version is not publicly available. That version of the database stores a lot of meta data, which logs information for each datapoint, such as the method, boundaries, age, level of peer review, ...etc. It also categorises each datapoint according to main and sub-material categories, e.g. aluminium > cast aluminium. This database gives us a good basis for analysing the data.
E18: This available version of the ICE database is compiled from the background database. The data collection for this updated version of ICE has now been able to focus on collecting data with a more consistent method and boundaries than was previously available. The latest background ICE database has been modified to accommodate new formats for collected data. This was needed due to the changes seen in the carbon footprint landscape since 2019, which is when the previous version of the ICE database was released.
E19: Notably, there has been a large increase in the availability of Environmental Product Declarations (EPDs) and improved accessibility of EPDs via EPD libraries. These EPDs, undertaken to the EU wide standard EN 15804, have offered a considerably larger and more consistent dataset than was previously available. In fact, EN 15804 EPDs have been be the main source of data for this version of the ICE database.
E21: ICE (Inventory of Carbon & Energy) Method Diagram
E22: A diagram showing the approach to developing the ICE database is shown below. Due to the increased methodological consistency that modern data brings, it was possible to introduce the quality filter earlier in the data collection process, before data is extracted from literature resources.
E29: ICE (Inventory of Carbon & Energy) Scope and Method
E30: The ICE database retains a cradle to (factory) gate scope. This is known as Module A1 to A3 in the EU wide standards EN 15978 and EN 15804, on sustainability assessment of construction works. The ICE database is a meta database, e.g. a database storing metadata about datapoints. As a meta database, the background ICE database contains datapoints with a wide range of method and boundaries. These are logged as meta data in the background database. The boundaries and methodological consistency of the data collected is much improved over previous versions of ICE, due mainly to an increase in carbon footprint standards. There is also considerable overlap between many of the main footprinting standards in regards to method and boundaries.
... E35: Statistics on the average carbon footprint calculation method of all data collected from the previous version (ICE V3.0) of the ICE database are presented below for context. Updated figures for ICE V4.0 onwards are to be reviewed in due course.
E36: Method Stated | G36: Fraction of All Data Collected | I36: Totals will not add to 100%. This is because some studies claim adherence to multiple footprint standards.
E37: EN 15804 Data | G37: 0.89057239
E38: ISO 14067 | G38: 0.043771044
E39: ISO 14044 Only | G39: 0.042648709
E40: No standardised method claimed | G40: 0.057800224
E42: ICE (Inventory of Carbon & Energy) Update Notes
E44: V4.1
E45: The ICE database version 4.1 contains updates to a small number of materials (bitumen and GGBS), but these materials have large changes in their embodied carbon and influence several important construction materials. The majority of material categories are unaffected by this update. A summary of the main changes are logged here.
E47: General update notes
E49: Description | G49: Update Notes
E50: Material Category Updates | G50: This update is in response to industry LCA methodological changes to bitumen and GGBS, resulting in significant changes to their emissions factors. The following material categories have been updated accordingly to reflect those changes: Asphalt, Bitumen, Cement & Mortar, Concrete.
E52: V4.0
E53: The ICE database version 4.0 contained a number of important updates over the previous version, V3.0 (2019) and V2.0 (2011). A summary of the main changes is logged here.
E55: General update notes
E57: Description | G57: Update Notes
E58: Background database updated | G58: The background database, which is not publicly accessible, has been updated. Noting ICE V3.0 data (where no updates have been made) have been kept in the previous format. This is because the target data is now EPDs (EN 15804), which are available in bulk volumes from EPD libraries utilising APIs.
E59: Updated Data Quality Indictors (V2.0) introduced | G59: Data quality indicators have been updated to V2.0 for all newly added material profiles. ICE V3.0 data will still utilise the original DQI (V1.0) until the data is next updated. See the data quality matrix worksheet.
E60: New material profiles added | G60: New material profiles have been added for Ceramic, Insulation, Paint, Plaster, Rubber and Vinyl in ICE V4.0. These profiles now provide more data, more statistics, more charts and more links to the references used for each material.
E61: Limited updates on carbon data for Cement, Concrete, Steel, and Timber | G61: Updated carbon data is available for Cement, Concrete, Steel, and Timber (CLT and Glulam only), based on limited updated to background factors and newly available data sources. See material profiles for further information.
E62: Updated ICE Machine Readable version | G62: The ICE Machine Readable version has been updated in alignment to the ICE V4.0 updates made in this database
E63: Updates to the Cement, mortar and concrete model | G63: See the separate excel file, which has been updated following updates to the core cement and concrete carbon factors. The tool allows users to model the embodied carbon of specific cement, mortar and concrete mixtures, including precast concrete.
E64: ICE V2.0 "Miscellaneous" GWP data removed | G64: GWP data references from ICE V2.0 "Miscellaneous" materials has been removed from ICE V4.0 due to the age of the source data, as this is now deemed too out of date for inclusion
E66: ICE (Inventory of Carbon & Energy) Material Profiles Last Reviewed Notes
E68: Material Profile | G68: Date Last Updated | I68: Notes
E69: Aggregates and Sand | G69: May 2019
E70: Aluminium | G70: May 2019
E71: Asphalt | G71: Oct 2025 | I71: Updates to incorporate the significant increase of the embodied carbon of Bitumen in Eurobitume's latest study (2025). Production emissions (A3) also updated with newer MPA sector average data.
...

Sheet Data Quality Matrix
E6: Data Quality Indicator (DQI) Matrix
E10: DQI Version: | F10: V2.0 | G10: Date DQI matrix last updated: | I10: 45631
E11: Version applied to: | F11: ICE V4.0 material profiles - Ceramics, Insulation, Paint, Plaster, Rubber, Stainless Steel, Vinyl
E12: Is this version still valid? | F12: Check link below, to see if a newer version is available.
E13: Check if this copy is up to date at: | F13: http://www.circularecology.com/embodied-energy-and-carbon-footprint-database.html
E16: Overview to DQI Scoring Framework
E17: The updated DQI scoring framework (V2.0) considers two separate DQI grouping to assess the quality of the material profile data: - Core DQIs for individual data points (50% weighting) - e.g., temporal correlation, geographical compatibility, method compatibility etc. - Calculated Average DQIs for material subcategories (50% weighting) - e.g., population and precision, analytical review approach etc. Further information on each of these DQI groupings can be found below.
E21: Core DQIs for individual data points e.g. EPDs
E22: These criteria are applied to all datapoints collected. The Core DQI scoring framework closely reflects the original DQI (V1.0) framework, noting some small modifications to the scoring allocations for each criteria, except for Assurance which has remained the same.
E25: Score | F25: 5 (Best) | G25: 4 | H25: 3 | I25: 2 | J25: 1 (Worst) | K25: Notes
E26: Method compatibility | F26: Industry-specific prescriptive standards (e.g. EN 15804, ISO 21930) | G26: Industry non-specific prescriptive standards (e.g. ISO 14067, PAS 2050, GHGP Product) - EPDs without stated methods will be awarded this score by default. | H26: Other standardised method | I26: Recognised method, but not standardised (e.g. ISO 14040/44 only) | J26: No declared method (e.g. missing data or research paper without defined method)
E27: Assurance | F27: External panel review (e.g. ISO 14040 panel review with 3 or more people) | G27: 2 External reviewers (e.g. academic papers) | H27: 1 External reviewer (EPDs score this by default) | I27: Internal review | J27: No declared review process
E28: Temporal correlation - Age of study | F28: <= 3 years old | G28: 4 - 6 years old | H28: 7 - 9 years old | I28: >= 10 years old | J28: No declared year
E29: Geographical compatibility | F29: UK | G29: European data or World Average | H29: North American | I29: All other countries and regions, or no declared geography | J29: - | K29: Note: Ideal boundaries of ICE DB are UK. This DQI is not a statement on quality of LCA data from various regions around the world.
E30: Transparency | F30: Full calculation model and detailed report available (very rare) | G30: Detailed report (e.g. full LCA report, documenting assumptions in detail), but no calculation model. Or transparent calculation model, but not detailed report. | H30: Summary report covering an overview of method incl. key data (EPDs will be awarded this score) | I30: - | J30: Limited details on method, or key information missing
E32: Category Average DQIs on material sub-categories:
E33: These criteria are not applicable to the individual datapoints collected in the background ICE database. They are applied to material categories and sub-categories that have used the average of all data collected. For example, if the data for a material was the average of '50' datapoints collected, the below additional data quality indicators will be applied. This is included so that, where statistical average data is used, the sample size, precision, and analytical approach can be considered as a part of the data quality score, e.g. larger datasets are more beneficial, and in theory better, and so this allows it to be reflected in the DQI score. For datapoints that were selected based upon a specific reference, these data quality indicators are not applied.
E36: Population & Precision DQI (Max 5 Points)
E37: The Population & Precision DQI is a quality assessment of material sub-categories, and takes into account the number of individual datapoints contributing to the statistical average, as well as the mean absolute percentage deviation (MAPD) which describes variance of the sample. MAPD is calculated as the average of absolute percentage deviations for all datapoints' GWP values against the mean GWP value for that material sub-category. This value represents the average absolute deviation (positive and negative deviations) of GWP from the mean for all datapoints within a given material sub-category. These two characteristics are represented in a matrix format to allow for flexibility of datasets to be fairly represented within this DQI scoring e.g. a large dataset with a very high MAPD value, may not be inherently preferable to a smaller dataset with a lower MAPD value. The final DQI score (max 5 points) is assigned based on the combination of the two characteristics, e.g. a material sub-category whose sample size is 50, and MAPD is 25%, would score 2.5 points.
E40: Sample Size / MAPD | F40: > 40% | G40: 40% ≥ x > 30% | H40: 30% ≥ x > 20% | I40: 20% ≥ x > 10% | J40: ≤ 10%
E41: 1 - 10 | F41: 0.5 | G41: 1 | H41: 1.5 | I41: 2 | J41: 2
E42: 11 - 25 | F42: 1 | G42: 1.5 | H42: 2 | I42: 2.5 | J42: 3
E43: 26 - 50 | F43: 1.5 | G43: 2 | H43: 2.5 | I43: 3 | J43: 3.5
E44: 51 - 100 | F44: 2 | G44: 2.5 | H44: 3 | I44: 3.5 | J44: 4.5
E45: 101+ | F45: 2 | G45: 3 | H45: 3.5 | I45: 4 | J45: 5
E47: Analytical DQI (Max 5 Points)
E48: When compiling individual datapoints into material sub-categories, different analytical and review processes were undertaken to ensure, as much as possible, the accuracy and suitability of data utilised within those sub-categories. These processes include, but are not limited to, inspecting anomalous results to verify that GWP and other key metric values are correct as stated in the original data source, or sense checking whether the cut-off methods and assessment boundaries are consistent to allow for fair comparisons between datapoints. The scoring allocations outlined below aim to reflect the analytical approach taken, based on available resource, and the status of any noted concerns outstanding at the end of this process. The Analytical DQI assigns a score (max 5 points) to the material sub-category based on these findings.
E51: Description | I51: Score | J51: Notes
E52: Every datapoint in this category has been checked, and all targeted analysis (e.g. via statistical methods, reference values, visual inspection) has been closed out satisfactorily | I52: 5 | J52: -
E53: Targeted analysis (e.g. via statistical methods, reference values, visual inspection) has been closed out satisfactorily, with minor or no concerns noted | I53: 4 | J53: Example of minor concern includes: identification of minor individual outliers within the dataset
E54: Targeted analysis (e.g. via statistical methods, reference values, visual inspection) has been closed out satisfactorily, with moderate concerns noted | I54: 3 | J54: Example of moderate concern includes: possible overlap of given datapoint(s) across multiple material sub-categories
E55: Targeted analysis (e.g. via statistical methods, reference values, visual inspection) has been closed out satisfactorily, with larger concerns noted | I55: 2 | J55: Example of larger concern includes: possible distortion of a dataset due to modelling inconsistencies such as unaccounted recycled content which can significantly affect average values for key metrics
E56: Data has been categorised, automatic capping applied, but no analysis or review of individual datapoints has taken place; or targeted analysis (e.g. via statistical methods, reference values, visual inspection) has been attempted but major concerns are noted | I56: 1 | J56: Example includes: a published dataset that otherwise does not satisfy the minimum required level of confidence to achieve the above higher scores.
E60: [PREVIOUS] Data Quality Indicator (DQI) Matrix
E65: DQI Version: | F65: V1.0 | G65: Date DQI matrix last updated: | I65: 43615
E66: Version applied to: | F66: All ICE V3.0 material profiles and ICE V4.0 / V4.1 - Cement_and_Mortar, Clay_Bricks, Concrete, Steel (excl. Stainless Steel), Timber
E68: Introduction
E69: Data quality indicators are used in this version of the ICE database, to assess the data quality of each datapoint collected. In order to do this, a data quality matrix is used and is applied to all of the data collected.
E72: Data quality for individual data, e.g. EPDs
E73: These criteria are applied to all datapoints collected.
...

Sheet >> ICE DB Summary >>
E6: Main ICE Database Summary Table >>>

Sheet ICE Summary
F6: INVENTORY OF CARBON & ENERGY (ICE) SUMMARY - V 4.1 | T6: Lookup Name In ICE DB [Hide these]
F10: ICE DB Version: | G10: =Miscellaneous!$E$3 -> V4.1 - Oct 2025 | I10: Check this link to see when the material profiles below were last updated
F11: Is this version still valid? | G11: Check link below, to see if a newer version is available. | J11: This version has expired. Please download a new version using the link below.
F12: Check if this copy is up to date at: | G12: http://www.circularecology.com/embodied-energy-and-carbon-footprint-database.html
F14: Introduction
F15: Materials covered in ICE V4.1 | G15: The updated ICE database, to ICE V4.1, has expanded on the data updates for the main construction materials provided in ICE V4.0 and ICE V3.0. This is following a pareto principle, also known as the 80:20 rule, to update the database within the level of resource that was available. Those materials should cover the majority of embodied carbon for many construction projects. It is appreciated that there are materials that haven't been updated, but which are still an important part of a materials inventory in construction, particularly on some projects. In order for users to be able to model the embodied carbon of these materials, the data from the previous versions of ICE, V3.0 (published in 2019) and V2.0 (published in 2011), have been copied to this summary.
F17: Aggregates and Sand
F19: Materials | G19: Embodied Carbon - kgCO2e/kg | J19: Comments | K19: DQI Score | L19: DQI Version | T19: Name Exactly as in ICE DB
F20: general UK, mixture of land won, marine, secondary and recycled, bulk, loose | G20: 0.0074696455 | J20: This is an estimate of a market average aggregate. It models a mixture of 64.2% land won, 27.5% recycled and secondary, and 8.3% marine aggregates. Consumption statistics have been taken from a report, by British Marine Aggregates Producer Association, a member of the Mineral Products Association (MPA). [Tenth sustainable development report for the British marine aggregate industry, Dec 2016]. These results are sensitive to the embodied carbon of secondary aggregates, which is a material where data would benefit from improvement. If you know the specific type of aggregates you will use, then it is recommended to use a more specific category of aggregates. | K20: 0.57223891 | L20: V1.0 | T20: Aggregates and sand, general UK, mixture of land won, marine, secondary and recycled, bulk, loose
F21: general, virgin mixture of land won and marine, bulk, loose | G21: 0.0049277889 | J21: Excludes recycled and secondary aggregate. This has been modelled with 89% land won and 11% marine won aggregate. Consumption statistics have been taken from a report, by British Marine Aggregates Producer Association, a member of the Mineral Products Association (MPA). [Tenth sustainable development report for the British marine aggregate industry, Dec 2016]. The consumption of marine aggregate was taken to be the total marine aggregate production. Of the total, 68% are consumed in the GB market, 11% are sent to the European market and 21% used as beach replenishment or fill. | K21: 0.56684369 | L21: V1.0 | T21: Aggregates and sand, general, virgin mixture of land won and marine, bulk, loose
F22: from virgin land won resources, bulk, loose | G22: 0.0043575012 | J22: Based upon the statistical average of all data collected for virgin aggregates in the ICE Database. | K22: 0.64818763 | L22: V1.0 | T22: Aggregates and sand, from virgin land won resources, bulk, loose
F23: from virgin marine resources, bulk, loose | G23: 0.0090375 | J23: Consumption statistics have been taken from a report, by British Marine Aggregates Producer Association, a member of the Mineral Products Association (MPA). [Tenth sustainable development report for the British marine aggregate industry, Dec 2016]. The consumption of marine aggregate was taken to be the total marine aggregate production. The data has been modelled with the average energy consumption for extracting marine aggregates in the UK. The original data did not use all scope emissions factors, instead just scope 1 and 2. The data was therefore used to estimate the full scope 1, 2 and 3 emissions. The impacts to produce aggregates has a particularly large variation in embodied impacts. | K23: 0.34285714 | L23: V1.0 | T23: Aggregates and sand, from virgin marine resources, bulk, loose
F24: from recycled resources, no heat treatment, bulk, loose | G24: 0.0060529786 | J24: Based upon the statistical average of all data collected for recycled aggregates with no heat treatment in the ICE Database. Recycled aggregates include aggregates from construction and demolition waste. It does not cover secondary aggregates, such as blast furnace slag, or bottom ash (see separate category for these). Data for recycled aggregates is more difficult to obtain than for virgin aggregates. There is also a large range in results for recycled aggregates, adding uncertainty into the results. | K24: 0.56122449 | L24: V1.0 | T24: Aggregates and sand, from recycled resources, no heat treatment, bulk, loose
F25: from recycled resources, with heat treatment, bulk, loose | G25: 0.11877167 | J25: Based upon the statistical average of all data collected for recycled aggregates that have been through heat treatment in the ICE Database. Recycled aggregates include aggregates from construction and demolition waste. It does not cover secondary aggregates such as blast furnace slag, or bottom ash (see separate category for these). Data for recycled aggregates is more difficult to obtain than for virgin aggregates. There is also a large range in results for recycled aggregates, adding uncertainty into the results. | K25: 0.44761905 | L25: V1.0 | T25: Aggregates and sand, from recycled resources, with heat treatment, bulk, loose
F26: expanded clay, bulk, loose | G26: 0.3350915 | J26: Based upon the statistical average of all data collected for expanded clay aggregates in the ICE Database. | K26: 0.48571429 | L26: V1.0 | T26: Aggregates and sand, expanded clay, bulk, loose
F27: expanded foamed glass, bulk, loose | G27: 0.273532 | J27: Based upon the statistical average of all data collected for expanded foamed glass aggregates in the ICE Database. | K27: 0.45714286 | L27: V1.0 | T27: Aggregates, expanded foamed glass, bulk, loose
F28: from secondary resources, bulk, loose | G28: 0.063323 | J28: Including blast furnace slag, bottom ashes, road planings, mining spoil and other aggregates manufactured from secondary resources. Limited data on the embodied carbon of secondary aggregates was available. There was also limited data on the consumption mixture of secondary aggregates in the UK. The mixture was estimated based upon two sub-regional reports for the Aggregate Minerals survey2015 (AM15). See the references [Table 6.1 in Ref: North East Aggregates Working Party, Annual Aggregates Monitoring report 2015, Dec 2016 ] and [Table 10B in South East Aggregates Working Party, South East Aggregates Monitoring report 2014 & 2015, Sept 2016]. The data would benefit from covering a wider share of the UK secondary aggregate market, | K28: 0.51428571 | L28: V1.0 | T28: Aggregates and sand, from secondary resources, bulk, loose
F29: mixture of recycled and secondary resources, bulk, loose | G29: 0.014181254 | J29: Data on recycled and (particularly) secondary aggregates would benefit from improvement. Limited data on the embodied carbon of secondary aggregates was available. There was also limited data on the consumption mixture of recycled and secondary aggregates in the UK. The mixture was modelled with 33% secondary and 67% recycled aggregates. [Estimated from Ref: Aggregates, cement and ready-mix concrete market investigation, Working paper on market definition for aggregates, cement and RMX. ND67. Available from: https://assets.publishing.service.gov.uk/media/5329dfb440f0b60a730002cf/market_definition_housestyled.pdf] | K29: 0.59042185 | L29: V1.0 | T29: Aggregates and sand, mixture of recycled and secondary resources, bulk, loose
F31: Aluminium
F33: The data for aluminium are based upon detailed LCAs from the World Aluminium Institute, http://www.world-aluminium.org/. Their LCA model is used as the basis for LCA's from the European Aluminium Institute, https://www.european-aluminium.eu/, as well as the North American Aluminium Association, https://www.aluminum.org/. The source LCAs reports generally don't combine the data for ingot with the semi-fabrication processes, such as casting, sheet production or extrusion. The below data has combined the data in the LCA's, to produce the values below. All data is modelled at the world average recycled material input, taken from the "Global Aluminium Flow Model 2016", available from http://www.world-aluminium.org/publications/. This approach of using world averages for all regions is to avoid market distortions. Should any users require data for other recycled contents, there is further information on the material profile for aluminium.
F35: European consumption - Includes European production and imports - At world average recycled content
F37: Materials | G37: Embodied Carbon - kgCO2e/kg | J37: Comments | K37: DQI Score | L37: DQI Version | T37: Name Exactly as in ICE DB
F38: Aluminium General, European Mix, Inc Imports | G38: 6.6687175 | J38: This data has been derived from the world aluminium LCA's. They have produced LCA reports for Europe, North America and worldwide aluminium. Modelled at worldwide average scrap input of 31%, to avoid market distortions. Modelled with 25.6% extrusions, 55.7% rolled and 18.7% castings. Based upon European production and the import of aluminium consumed in Europe. Module D = -3.13 kg CO2e per unit. EOL recovery rate of 95%, based upon DU Telft study of European construction sector. With a 2% material loss yield on the scrap recovered. | K38: 0.64 | L38: V1.0 | T38: Aluminium General, European Mix, Inc Imports
F39: Aluminium sheet, European Mix, Inc Imports | G39: 6.581176 | J39: This data has been derived from the world aluminium LCA's. They have produced LCA reports for Europe, North America and worldwide aluminium. Modelled at worldwide average scrap input of 31%, to avoid market distortions. Based upon European production and the import of aluminium consumed in Europe. Module D = -3.09 kg CO2e per unit. EOL recovery rate of 95%, based upon DU Telft study of European construction sector. With a 2% material loss yield on the scrap recovered. | K39: 0.64 | L39: V1.0 | T39: Aluminium sheet, European Mix, Inc Imports
F40: Aluminium foil, European Mix, Inc Imports | G40: 7.468978 | J40: This data has been derived from the world aluminium LCA's. They have produced LCA reports for Europe, North America and worldwide aluminium. Modelled at worldwide average scrap input of 31%, to avoid market distortions. Based upon European production and the import of aluminium consumed in Europe. Module D = -3.54 kg CO2e per unit. EOL recovery rate of 95%, based upon DU Telft study of European construction sector. With a 2% material loss yield on the scrap recovered. | K40: 0.64 | L40: V1.0 | T40: Aluminium foil, European Mix, Inc Imports
F41: Aluminium extruded profile, European Mix, Inc Imports | G41: 6.825242 | J41: This data has been derived from the world aluminium LCA's. They have produced LCA reports for Europe, North America and worldwide aluminium. Modelled at worldwide average scrap input of 31%, to avoid market distortions. Based upon European production and the import of aluminium consumed in Europe. Module D = -3.21 kg CO2e per unit. EOL recovery rate of 95%, based upon DU Telft study of European construction sector. With a 2% material loss yield on the scrap recovered. | K41: 0.64 | L41: V1.0 | T41: Aluminium extruded profile, European Mix, Inc Imports
F42: Aluminium, cast, European Mix, Inc Imports | G42: 6.7151901 | J42: This data has been derived from the world aluminium LCA's. They have produced LCA reports for Europe, North America and worldwide aluminium. Modelled at worldwide average scrap input of 31%, to avoid market distortions. Based upon European production and the import of aluminium consumed in Europe. Module D = -3.12 kg CO2e per unit. EOL recovery rate of 83%, based upon worldwide global aluminium flow model and for the building and construction sector. With a 2% material loss yield on the scrap recovered. | K42: 0.64 | L42: V1.0 | T42: Aluminium, cast, European Mix, Inc Imports
F44: Worldwide production - At world average recycled content
F46: Materials | G46: Embodied Carbon - kgCO2e/kg | J46: Comments | K46: DQI Score | L46: DQI Version | T46: Name Exactly as in ICE DB
F47: Aluminium General, Worldwide | G47: 13.05554 | J47: This data has been derived from the world aluminium LCA's. They have produced LCA reports for Europe, North America and worldwide aluminium. Modelled at worldwide average scrap input of 31%, to avoid market distortions. Modelled with 25.6% extrusions, 55.7% rolled and 18.7% castings. Module D = -8.69 kg CO2e per unit. EOL recovery rate of 83%, based upon worldwide global aluminium flow model and for the building and construction sector. With a 2% material loss yield on the scrap recovered. | K47: 0.64 | L47: V1.0 | T47: Aluminium General, Worldwide
F48: Aluminium sheet, Worldwide | G48: 12.955895 | J48: This data has been derived from the world aluminium LCA's. They have produced LCA reports for Europe, North America and worldwide aluminium. Modelled at worldwide average scrap input of 31%, to avoid market distortions. Module D = -8.69 kg CO2e per unit. EOL recovery rate of 83%, based upon worldwide global aluminium flow model and for the building and construction sector. With a 2% material loss yield on the scrap recovered. | K48: 0.64 | L48: V1.0 | T48: Aluminium sheet, Worldwide
F49: Aluminium foil, Worldwide | G49: 13.766895 | J49: This data has been derived from the world aluminium LCA's. They have produced LCA reports for Europe, North America and worldwide aluminium. Modelled at worldwide average scrap input of 31%, to avoid market distortions. Module D = -8.69 kg CO2e per unit. EOL recovery rate of 83%, based upon worldwide global aluminium flow model and for the building and construction sector. With a 2% material loss yield on the scrap recovered. | K49: 0.64 | L49: V1.0 | T49: Aluminium foil, Worldwide
F50: Aluminium extruded profile, Worldwide | G50: 13.176395 | J50: This data has been derived from the world aluminium LCA's. They have produced LCA reports for Europe, North America and worldwide aluminium. Modelled at worldwide average scrap input of 31%, to avoid market distortions. Module D = -8.69 kg CO2e per unit. EOL recovery rate of 83%, based upon worldwide global aluminium flow model and for the building and construction sector. With a 2% material loss yield on the scrap recovered. | K50: 0.64 | L50: V1.0 | T50: Aluminium extruded profile, Worldwide
F51: Aluminium cast, Worldwide | G51: 13.186895 | J51: This data has been derived from the world aluminium LCA's. They have produced LCA reports for Europe, North America and worldwide aluminium. Modelled at worldwide average scrap input of 31%, to avoid market distortions. Module D = -8.69 kg CO2e per unit. EOL recovery rate of 83%, based upon worldwide global aluminium flow model and for the building and construction sector. With a 2% material loss yield on the scrap recovered. | K51: 0.64 | L51: V1.0 | T51: Aluminium cast, Worldwide
F53: Regional aluminium - At world average recycled content
F55: Materials | G55: Embodied Carbon - kgCO2e/kg | J55: Comments | K55: DQI Score | L55: DQI Version | T55: Name Exactly as in ICE DB
F56: Aluminium General, European Mix, Inc Imports | G56: 6.6687175 | J56: This data has been derived from the world aluminium LCA's. They have produced LCA reports for Europe, North America and worldwide aluminium. Modelled at worldwide average scrap input of 31%, to avoid market distortions. Modelled with 25.6% extrusions, 55.7% rolled and 18.7% castings. Based upon European production and the import of aluminium consumed in Europe. Module D = -3.13 kg CO2e per unit. EOL recovery rate of 95%, based upon DU Telft study of European construction sector. With a 2% material loss yield on the scrap recovered. | K56: 0.64 | L56: V1.0 | T56: Aluminium General, European Mix, Inc Imports
F57: Aluminium, produced in Europe | G57: 5.5839382 | J57: This data has been derived from the world aluminium LCA's. They have produced LCA reports for Europe, North America and worldwide aluminium. Modelled at worldwide average scrap input of 31%, to avoid market distortions. This entry doesn’t consider aluminium imported into Europe. The aluminium must be made in Europe. Modelled with 25.6% extrusions, 55.7% rolled and 18.7% castings. Module D = -3.64 kg CO2e per unit. EOL recovery rate of 83%, based upon worldwide global aluminium flow model and for the building and construction sector. With a 2% material loss yield on the scrap recovered. | K57: 0.64 | L57: V1.0 | T57: Aluminium, produced in Europe
F58: Aluminium General, Worldwide | G58: 13.05554 | J58: This data has been derived from the world aluminium LCA's. They have produced LCA reports for Europe, North America and worldwide aluminium. Modelled at worldwide average scrap input of 31%, to avoid market distortions. Modelled with 25.6% extrusions, 55.7% rolled and 18.7% castings. Module D = -8.69 kg CO2e per unit. EOL recovery rate of 83%, based upon worldwide global aluminium flow model and for the building and construction sector. With a 2% material loss yield on the scrap recovered. | K58: 0.64 | L58: V1.0 | T58: Aluminium General, Worldwide
F59: Aluminium, North American | G59: 5.651616 | J59: This data has been derived from the world aluminium LCA's. They have produced LCA reports for Europe, North America and worldwide aluminium. Modelled at worldwide average scrap input of 31%, to avoid market distortions. Modelled with 25.6% extrusions, 55.7% rolled and 18.7% castings. Module D = -3.69 kg CO2e per unit. EOL recovery rate of 83%, based upon worldwide global aluminium flow model and for the building and construction sector. With a 2% material loss yield on the scrap recovered. | K59: 0.64 | L59: V1.0 | T59: Aluminium, North American
...

Sheet >> Material Profiles >>
E6: Material Profiles >>>

Sheet Aggregates_Sand
A1: THESE ROWS AND COLUMNS WILL BE HIDDEN - They contain update notes and information for lookup calculations
F2: SELECT Material | G2: AggregateSand | I2: Hide these rows, used for lookup formulas
F3: Sheet name | G3: =MID(CELL("filename",A1),FIND("]",CELL("filename",A1))+1,255) -> Aggregates_Sand
F4: Workbook name | G4: =MID(CELL("filename",A1),FIND("[",CELL("filename",A1))+1,FIND("]", CELL("filename",A1))-FIND("[",CELL("filename",A1))-1) -> ICE DB Educational V4.1 - Oct 2025.xlsx
B6: Edit Title Manually | F6: Material Profile: Aggregates & Sand
F7: ICE DB Version: | G7: =Miscellaneous!$E$3 -> V4.1 - Oct 2025 | J7: Check this link to see when the material profile was last updated
B8: Update URL Manually | F8: This material profile is provided in full to demonstrate the format and scope of the information provided in the Advanced version. For access to all material profiles, please refer to the advanced version using the links below:
F9: Is this version still valid? | H9: Check link below, to see if a newer version is available. | K9: This version has expired. Please download a new version using the link below.
F10: Check if this copy is up to date at: | H10: http://www.circularecology.com/embodied-energy-and-carbon-footprint-database.html
F17: Section Navigation
F19: Section - Click to Go | J19: Comments
A20: A51 | B20: =CONCATENATE("#",$G$3,"!"&A20) -> #Aggregates_Sand!A51 | C20: Introduction to Material | F20: =HYPERLINK(B20,C20) -> Introduction to Material | J20: Notes on the embodied carbon of this material. This may include some important information.
A21: A60 | B21: =CONCATENATE("#",$G$3,"!"&A21) -> #Aggregates_Sand!A60 | C21: Selected Embodied Carbon Coefficients | F21: =HYPERLINK(B21,C21) -> Selected Embodied Carbon Coefficients | J21: These are the main embodied carbon footprint coefficients for the material types.
A22: A483 | B22: =CONCATENATE("#",$G$3,"!"&A22) -> #Aggregates_Sand!A483 | C22: Wider Life Cycle Notes | F22: =HYPERLINK(B22,C22) -> Wider Life Cycle Notes | J22: Notes on wider life cycle impacts.
A23: A495 | B23: =CONCATENATE("#",$G$3,"!"&A23) -> #Aggregates_Sand!A495 | C23: ICE Database Embodied Carbon (EC) Statistics - kg CO2e/kg | F23: =HYPERLINK(B23,C23) -> ICE Database Embodied Carbon (EC) Statistics - kg CO2e/kg | J23: Here you will find detailed statistics on the data collected. For the full list of all datapoints, a separate section is included further below.
A24: A533 | B24: =CONCATENATE("#",$G$3,"!"&A24) -> #Aggregates_Sand!A533 | C24: Histograms and distribution charts | F24: =HYPERLINK(B24,C24) -> Histograms and distribution charts | J24: For some of the sub-material categories, histograms and embodied carbon distribution charts have been included.
A25: A583 | B25: =CONCATENATE("#",$G$3,"!"&A25) -> #Aggregates_Sand!A583 | C25: Data Quality | F25: =HYPERLINK(B25,C25) -> Data Quality | J25: The data within the ICE Database is rated for data quality. The average data quality is shown here, along with a link to the data quality matrix.
A26: A759 | B26: =CONCATENATE("#",$G$3,"!"&A26) -> #Aggregates_Sand!A759 | C26: Material Properties | F26: =HYPERLINK(B26,C26) -> Material Properties | J26: Information on material density, specific heat, and more.
A27: A776 | B27: =CONCATENATE("#",$G$3,"!"&A27) -> #Aggregates_Sand!A776 | C27: All Data Points | F27: =HYPERLINK(B27,C27) -> All Data Points | J27: Here you will find a list of all the datapoints collected. These datapoints are used to produce the histograms and may be useful for further statistical analysis.
A28: A1072 | B28: =CONCATENATE("#",$G$3,"!"&A28) -> #Aggregates_Sand!A1072 | C28: Further Reading | F28: =HYPERLINK(B28,C28) -> Further Reading | J28: A list of recommended reading.
A29: A1799 | B29: =CONCATENATE("#",$G$3,"!"&A29) -> #Aggregates_Sand!A1799 | C29: References and EPDs | F29: =HYPERLINK(B29,C29) -> References and EPDs | J29: The ICE Database uses data from multiple resources. However, EPDs have become the most important data resource. Here you will find reference details and links to EPDs for this material.
B30: =CONCATENATE("#",$G$3,"!"&A30) -> #Aggregates_Sand! | C30: INSERT LINK TO WEBPAGE FOR MATERIAL PROFILE | F30: =HYPERLINK(B30,C30) -> INSERT LINK TO WEBPAGE FOR MATERIAL PROFILE | J30: For further information, please visit the webpage for this material profile.
B36: CUSTOMISE WHOLE SECTION FOR MATERIAL | F36: Introduction to Material
F37: Data for aggregates has a particularly notable embodied carbon range. There are also many different types of aggregates. ICE V2.0 only contained data for general aggregates. The ICE database now contains data for many different types of aggregates, including land won, marine, recycled and secondary aggregates. The data suggests that for most types of aggregates there is a wide range of embodied carbon. There is also a notable difference in the embodied carbon of virgin and non-virgin aggregates (recycled and secondary). The data suggests that virgin aggregates may have a lower embodied carbon of production. However, every case should be judged on an individual basis. It is important to consider with aggregates that carbon is only one of many environmental and resource use indicators. Whilst there are cases here recycled or secondary aggregates may be higher embodied carbon than virgin aggregates, it should also be considered that embodied carbon does not consider any of the wider resource use benefits. The use of recycled resources, reduces the burden on virgin resources. This is something that embodied carbon assessment doesn't consider adequately. Embodied carbon data for recycled and secondary aggregates would benefit from improvement. Data for secondary aggregates was particularly poor. Likewise, data on the consumption mixture of secondary and recycled aggregates was limited and would benefit from improvement.
F46: Boundaries: | G46: Cradle to Gate = A1-A3
B49: COPY FROM SUMMARY TABLE | F49: Selected Embodied Carbon Coefficients
F51: Comments
F52: There is a notable embodied carbon range for most types of aggregates, as well as for different types of aggregates. It is therefore recommended to use data on specific types of aggregates, over the data for UK general aggregates, where possible. This is because the data on secondary and recycled aggregates influences the average notably.
F57: <<< Start of Main Embodied Carbon Data >>>
F59: Materials | G59: Embodied Carbon - kgCO2e/kg | H59: Comments | M59: DQI Score | N59: DQI Version | T59: Name Exactly as in ICE DB
F60: Aggregates and sand, general UK, mixture of land won, marine, secondary and recycled, bulk, loose | G60: 0.0074696455 | H60: This is an estimate of a market average aggregate. It models a mixture of 64.2% land won, 27.5% recycled and secondary, and 8.3% marine aggregates. Consumption statistics have been taken from a report, by British Marine Aggregates Producer Association, a member of the Mineral Products Association (MPA). [Tenth sustainable development report for the British marine aggregate industry, Dec 2016]. These results are sensitive to the embodied carbon of secondary aggregates, which is a material where data would benefit from improvement. If you know the specific type of aggregates you will use, then it is recommended to use a more specific category of aggregates. | M60: 0.57223891 | N60: V1.0 | T60: Aggregates and sand, general UK, mixture of land won, marine, secondary and recycled, bulk, loose
F61: Aggregates and sand, general, virgin mixture of land won and marine, bulk, loose | G61: 0.0049277889 | H61: Excludes recycled and secondary aggregate. This has been modelled with 89% land won and 11% marine won aggregate. Consumption statistics have been taken from a report, by British Marine Aggregates Producer Association, a member of the Mineral Products Association (MPA). [Tenth sustainable development report for the British marine aggregate industry, Dec 2016]. The consumption of marine aggregate was taken to be the total marine aggregate production. Of the total, 68% are consumed in the GB market, 11% are sent to the European market and 21% used as beach replenishment or fill. | M61: 0.56684369 | N61: V1.0 | T61: Aggregates and sand, general, virgin mixture of land won and marine, bulk, loose
F62: Aggregates and sand, from virgin land won resources, bulk, loose | G62: 0.0043575012 | H62: Based upon the statistical average of all data collected for virgin aggregates in the ICE Database. | M62: 0.64818763 | N62: V1.0 | T62: Aggregates and sand, from virgin land won resources, bulk, loose
F63: Aggregates and sand, from virgin marine resources, bulk, loose | G63: 0.0090375 | H63: Consumption statistics have been taken from a report, by British Marine Aggregates Producer Association, a member of the Mineral Products Association (MPA). [Tenth sustainable development report for the British marine aggregate industry, Dec 2016]. The consumption of marine aggregate was taken to be the total marine aggregate production. The data has been modelled with the average energy consumption for extracting marine aggregates in the UK. The original data did not use all scope emissions factors, instead just scope 1 and 2. The data was therefore used to estimate the full scope 1, 2 and 3 emissions. The impacts to produce aggregates has a particularly large variation in embodied impacts. | M63: 0.34285714 | N63: V1.0 | T63: Aggregates and sand, from virgin marine resources, bulk, loose
F64: Aggregates and sand, from recycled resources, no heat treatment, bulk, loose | G64: 0.0060529786 | H64: Based upon the statistical average of all data collected for recycled aggregates with no heat treatment in the ICE Database. Recycled aggregates include aggregates from construction and demolition waste. It does not cover secondary aggregates, such as blast furnace slag, or bottom ash (see separate category for these). Data for recycled aggregates is more difficult to obtain than for virgin aggregates. There is also a large range in results for recycled aggregates, adding uncertainty into the results. | M64: 0.56122449 | N64: V1.0 | T64: Aggregates and sand, from recycled resources, no heat treatment, bulk, loose
F65: Aggregates and sand, from recycled resources, with heat treatment, bulk, loose | G65: 0.11877167 | H65: Based upon the statistical average of all data collected for recycled aggregates that have been through heat treatment in the ICE Database. Recycled aggregates include aggregates from construction and demolition waste. It does not cover secondary aggregates such as blast furnace slag, or bottom ash (see separate category for these). Data for recycled aggregates is more difficult to obtain than for virgin aggregates. There is also a large range in results for recycled aggregates, adding uncertainty into the results. | M65: 0.44761905 | N65: V1.0 | T65: Aggregates and sand, from recycled resources, with heat treatment, bulk, loose
F66: Aggregates and sand, expanded clay, bulk, loose | G66: 0.3350915 | H66: Based upon the statistical average of all data collected for expanded clay aggregates in the ICE Database. | M66: 0.48571429 | N66: V1.0 | T66: Aggregates and sand, expanded clay, bulk, loose
F67: Aggregates, expanded foamed glass, bulk, loose | G67: 0.273532 | H67: Based upon the statistical average of all data collected for expanded foamed glass aggregates in the ICE Database. | M67: 0.45714286 | N67: V1.0 | T67: Aggregates, expanded foamed glass, bulk, loose
F68: Aggregates and sand, from secondary resources, bulk, loose | G68: 0.063323 | H68: Including blast furnace slag, bottom ashes, road planings, mining spoil and other aggregates manufactured from secondary resources. Limited data on the embodied carbon of secondary aggregates was available. There was also limited data on the consumption mixture of secondary aggregates in the UK. The mixture was estimated based upon two sub-regional reports for the Aggregate Minerals survey2015 (AM15). See the references [Table 6.1 in Ref: North East Aggregates Working Party, Annual Aggregates Monitoring report 2015, Dec 2016 ] and [Table 10B in South East Aggregates Working Party, South East Aggregates Monitoring report 2014 & 2015, Sept 2016]. The data would benefit from covering a wider share of the UK secondary aggregate market, | M68: 0.51428571 | N68: V1.0 | T68: Aggregates and sand, from secondary resources, bulk, loose
